<?xml version="1.0" encoding="UTF-8"?>
<!-- Generated by org.testng.reporters.JUnitXMLReporter -->
<testsuite hostname="MOCDTL01MM847H" ignored="0" name="Test1" tests="9" failures="3" timestamp="17 Sep 2018 09:50:37 GMT" time="49.923" errors="0">
  <testcase name="launchAndNavigate" time="26.348" classname="com.branch.qatest.BranchTest"/>
  <testcase name="ReadAllTab" time="4.269" classname="com.branch.qatest.BranchTest"/>
  <testcase name="readDepartmentTabs" time="5.634" classname="com.branch.qatest.BranchTest"/>
  <testcase name="compareNames" time="0.0" classname="com.branch.qatest.BranchTest">
    <failure type="java.lang.AssertionError" message="expected [true] but found [false]">
      <![CDATA[java.lang.AssertionError: expected [true] but found [false]
at com.branch.qatest.BranchTest.compareNames(BranchTest.java:302)
at java.util.concurrent.FutureTask.run(Unknown Source)
at java.util.concurrent.ThreadPoolExecutor.runWorker(Unknown Source)
at java.util.concurrent.ThreadPoolExecutor$Worker.run(Unknown Source)
at java.lang.Thread.run(Unknown Source)
... Removed 20 stack frames]]>
    </failure>
  </testcase> <!-- compareNames -->
  <testcase name="compareDepartments" time="0.23" classname="com.branch.qatest.BranchTest"/>
  <testcase name="checkForSumOfEmployeesAcrossTabs" time="0.0" classname="com.branch.qatest.BranchTest">
    <failure type="java.lang.AssertionError" message="expected [119] but found [124]">
      <![CDATA[java.lang.AssertionError: expected [119] but found [124]
at com.branch.qatest.BranchTest.checkForSumOfEmployeesAcrossTabs(BranchTest.java:287)
at java.util.concurrent.FutureTask.run(Unknown Source)
at java.util.concurrent.ThreadPoolExecutor.runWorker(Unknown Source)
at java.util.concurrent.ThreadPoolExecutor$Worker.run(Unknown Source)
at java.lang.Thread.run(Unknown Source)
... Removed 22 stack frames]]>
    </failure>
  </testcase> <!-- checkForSumOfEmployeesAcrossTabs -->
  <testcase name="checkForOneEmployeeInEveryDepartment" time="0.02" classname="com.branch.qatest.BranchTest"/>
  <testcase name="test_ValidDepartmentNames" time="6.777" classname="com.branch.qatest.BranchTest"/>
  <testcase name="test_employeeSocialAccount" time="6.611" classname="com.branch.qatest.BranchTest">
    <failure type="java.lang.IndexOutOfBoundsException" message="Index: 124, Size: 124">
      <![CDATA[java.lang.IndexOutOfBoundsException: Index: 124, Size: 124
at java.util.ArrayList.rangeCheck(Unknown Source)
at java.util.ArrayList.get(Unknown Source)
at com.branch.qatest.BranchTest.test_employeeSocialAccount(BranchTest.java:495)
at java.util.concurrent.FutureTask.run(Unknown Source)
at java.util.concurrent.ThreadPoolExecutor.runWorker(Unknown Source)
at java.util.concurrent.ThreadPoolExecutor$Worker.run(Unknown Source)
at java.lang.Thread.run(Unknown Source)
... Removed 16 stack frames]]>
    </failure>
  </testcase> <!-- test_employeeSocialAccount -->
</testsuite> <!-- Test1 -->
