<?xml version="1.0" encoding="UTF-8"?>
<!-- Generated by org.testng.reporters.JUnitXMLReporter -->
<testsuite hostname="MOCDTL01MM847H" ignored="0" name="Test" tests="9" failures="3" timestamp="17 Sep 2018 10:08:05 GMT" time="285.897" errors="0">
  <testcase name="launchAndNavigate" time="22.047" classname="com.branch.qatest.BranchTest"/>
  <testcase name="ReadAllTab" time="9.092" classname="com.branch.qatest.BranchTest"/>
  <testcase name="readDepartmentTabs" time="241.587" classname="com.branch.qatest.BranchTest"/>
  <testcase name="compareNames" time="0.02" classname="com.branch.qatest.BranchTest">
    <failure type="java.lang.AssertionError" message="expected [true] but found [false]">
      <![CDATA[java.lang.AssertionError: expected [true] but found [false]
at com.branch.qatest.BranchTest.compareNames(BranchTest.java:305)
at java.util.concurrent.FutureTask.run(Unknown Source)
at java.util.concurrent.ThreadPoolExecutor.runWorker(Unknown Source)
at java.util.concurrent.ThreadPoolExecutor$Worker.run(Unknown Source)
at java.lang.Thread.run(Unknown Source)
... Removed 20 stack frames]]>
    </failure>
  </testcase> <!-- compareNames -->
  <testcase name="compareDepartments" time="0.19" classname="com.branch.qatest.BranchTest"/>
  <testcase name="checkForSumOfEmployeesAcrossTabs" time="0.01" classname="com.branch.qatest.BranchTest">
    <failure type="java.lang.AssertionError" message="expected [119] but found [124]">
      <![CDATA[java.lang.AssertionError: expected [119] but found [124]
at com.branch.qatest.BranchTest.checkForSumOfEmployeesAcrossTabs(BranchTest.java:290)
at java.util.concurrent.FutureTask.run(Unknown Source)
at java.util.concurrent.ThreadPoolExecutor.runWorker(Unknown Source)
at java.util.concurrent.ThreadPoolExecutor$Worker.run(Unknown Source)
at java.lang.Thread.run(Unknown Source)
... Removed 22 stack frames]]>
    </failure>
  </testcase> <!-- checkForSumOfEmployeesAcrossTabs -->
  <testcase name="checkForOneEmployeeInEveryDepartment" time="0.01" classname="com.branch.qatest.BranchTest"/>
  <testcase name="test_ValidDepartmentNames" time="6.928" classname="com.branch.qatest.BranchTest"/>
  <testcase name="test_employeeSocialAccount" time="5.951" classname="com.branch.qatest.BranchTest">
    <failure type="java.lang.IndexOutOfBoundsException" message="Index: 124, Size: 124">
      <![CDATA[java.lang.IndexOutOfBoundsException: Index: 124, Size: 124
at java.util.ArrayList.rangeCheck(Unknown Source)
at java.util.ArrayList.get(Unknown Source)
at com.branch.qatest.BranchTest.test_employeeSocialAccount(BranchTest.java:498)
at java.util.concurrent.FutureTask.run(Unknown Source)
at java.util.concurrent.ThreadPoolExecutor.runWorker(Unknown Source)
at java.util.concurrent.ThreadPoolExecutor$Worker.run(Unknown Source)
at java.lang.Thread.run(Unknown Source)
... Removed 16 stack frames]]>
    </failure>
  </testcase> <!-- test_employeeSocialAccount -->
</testsuite> <!-- Test -->
